Workbook

Sheet b3Setorial
A1: CLASSIFICAÇÃO SETORIAL DAS EMPRESAS NEGOCIADAS NA B3
A7: SETOR ECONÔMICO | B7: SUBSETOR | C7: SEGMENTO | D7: LISTAGEM
D8: CÓDIGO | E8: SEGMENTO
A9: Petróleo, Gás e Biocombustíveis | B9: Petróleo, Gás e Biocombustíveis | C9: Exploração, Refino e Distribuição
C10: COSAN | D10: CSAN | E10: NM
C11: DOMMO | D11: DMMO
C12: ENAUTA PART | D12: ENAT | E12: NM
C13: PET MANGUINH | D13: RPMG
C14: PETROBRAS | D14: PETR | E14: N2
C15: PETROBRAS BR | D15: BRDT | E15: NM
C16: PETRORIO | D16: PRIO | E16: NM
C17: ULTRAPAR | D17: UGPA | E17: NM
C18: Equipamentos e Serviços
C19: LUPATECH | D19: LUPA | E19: NM
C20: OSX BRASIL | D20: OSXB | E20: NM
A22: SETOR ECONÔMICO | B22: SUBSETOR | C22: SEGMENTO | D22: LISTAGEM
D23: CÓDIGO | E23: SEGMENTO
A24: Materiais Básicos | B24: Mineração | C24: Minerais Metálicos
C25: BRADESPAR | D25: BRAP | E25: N1
C26: LITEL | D26: LTEL | E26: MB
C27: LITELA | D27: LTLA | E27: MB
C28: MMX MINER | D28: MMXM | E28: NM
C29: VALE | D29: VALE | E29: NM
B30: Siderurgia e Metalurgia | C30: Siderurgia
C31: FERBASA | D31: FESA | E31: N1
C32: GERDAU | D32: GGBR | E32: N1
C33: GERDAU MET | D33: GOAU | E33: N1
C34: SID NACIONAL | D34: CSNA
C35: USIMINAS | D35: USIM | E35: N1
C36: Artefatos de Ferro e Aço
C37: MANGELS INDL | D37: MGEL
C38: PANATLANTICA | D38: PATI
C39: TEKNO | D39: TKNO
C40: Artefatos de Cobre
C41: PARANAPANEMA | D41: PMAM | E41: NM
B42: Químicos | C42: Petroquímicos
C43: BRASKEM | D43: BRKM | E43: N1
C44: ELEKEIROZ | D44: ELEK
C45: GPC PART | D45: GPCP
C46: Fertilizantes e Defensivos
...

Sheet Tabela_Auxiliar
A1: Ticker | B1: Nome | C1: SETOR ECONÔMICO | D1: SUBSETOR | E1: SEGMENTO
A2: AALR | B2: ALLIAR | C2: Saúde | D2: Análises e Diagnósticos | E2: Análises e Diagnósticos
A3: ABCB | B3: ABC BRASIL | C3: Financeiro | D3: Intermediários Financeiros | E3: Bancos
A4: ABEV | B4: AMBEV S/A | C4: Consumo não Cíclico | D4: Bebidas | E4: Cervejas e Refrigerantes
A5: ADHM | B5: ADVANCED-DH | C5: Saúde | D5: Análises e Diagnósticos | E5: Análises e Diagnósticos
A6: AESL | B6: AES SUL | C6: Utilidade Pública | D6: Energia Elétrica | E6: Energia Elétrica
A7: AFLT | B7: AFLUENTE T | C7: Utilidade Pública | D7: Energia Elétrica | E7: Energia Elétrica
A8: AGRO | B8: BRASILAGRO | C8: Consumo não Cíclico | D8: Agropecuária | E8: Agricultura
A9: AGRU | B9: GRUAIRPORT | C9: Bens Industriais | D9: Transporte | E9: Serviços de Apoio e Armazenagem
A10: AHEB | B10: SPTURIS | C10: Consumo Cíclico | D10: Viagens e Lazer | E10: Produção de Eventos e Shows
A11: ALEF | B11: ALEF S/A | C11: Outros | D11: Outros | E11: Outros
A12: ALGT | B12: ALGAR TELEC | C12: Comunicações | D12: Telecomunicações | E12: Telecomunicações
... A107: COCE | B107: COELCE | C107: Utilidade Pública | D107: Energia Elétrica | E107: Energia Elétrica
A108: CÓDIGO | B108: 0 | C108: Petróleo, Gás e Biocombustíveis | D108: Petróleo, Gás e Biocombustíveis | E108: Equipamentos e Serviços
A109: CÓDIGO | B109: 0 | C109: Materiais Básicos | D109: Materiais Diversos | E109: Materiais Diversos
A110: CÓDIGO | B110: 0 | C110: Bens Industriais | D110: Comércio | E110: Material de Transporte
A111: CÓDIGO | B111: 0 | C111: Consumo não Cíclico | D111: Comércio e Distribuição | E111: Alimentos
A112: CÓDIGO | B112: 0 | C112: Consumo Cíclico | D112: Tecidos, Vestuário e Calçados | E112: Acessórios
A113: CÓDIGO | B113: 0 | C113: Consumo Cíclico | D113: Comércio | E113: Produtos Diversos
A114: CÓDIGO | B114: 0 | C114: Saúde | D114: Comércio e Distribuição | E114: Medicamentos e Outros Produtos
A115: CÓDIGO | B115: 0 | C115: Tecnologia da Informação | D115: Programas e Serviços | E115: Programas e Serviços
A116: CÓDIGO | B116: 0 | C116: Comunicações | D116: Mídia | E116: Produção e Difusão de Filmes e Programas
A117: CÓDIGO | B117: 0 | C117: Utilidade Pública | D117: Gás | E117: Gás
A118: CÓDIGO | B118: 0 | C118: Financeiro | D118: Previdência e Seguros | E118: Corretoras de Seguros
A119: CÓDIGO | B119: 0 | C119: Financeiro | D119: Outros Títulos | E119: Outros Títulos
A120: COGN | B120: COGNA ON | C120: Consumo Cíclico | D120: Diversos | E120: Serviços Educacionais
A121: COLN | B121: ROD COLINAS | C121: Bens Industriais | D121: Transporte | E121: Exploração de Rodovias
A122: CORR | B122: COR RIBEIRO | C122: Financeiro | D122: Exploração de Imóveis | E122: Exploração de Imóveis
A123: CPFE | B123: CPFL ENERGIA | C123: Utilidade Pública | D123: Energia Elétrica | E123: Energia Elétrica
A124: CPFG | B124: CPFL GERACAO | C124: Utilidade Pública | D124: Energia Elétrica | E124: Energia Elétrica
A125: CPFP | B125: CPFL PIRATIN | C125: Utilidade Pública | D125: Energia Elétrica | E125: Energia Elétrica
A126: CPLE | B126: COPEL | C126: Utilidade Pública | D126: Energia Elétrica | E126: Energia Elétrica
A127: CPRE | B127: CPFL RENOVAV | C127: Utilidade Pública | D127: Energia Elétrica | E127: Energia Elétrica
A128: CPTE | B128: CACHOEIRA | C128: Utilidade Pública | D128: Energia Elétrica | E128: Energia Elétrica
A129: CPTP | B129: CAPITALPART | C129: Outros | D129: Outros | E129: Outros
A130: CRBD | B130: RT BANDEIRAS | C130: Bens Industriais | D130: Transporte | E130: Exploração de Rodovias
A131: CRDE | B131: CR2 | C131: Consumo Cíclico | D131: Construção Civil | E131: Incorporações
... A247: LIPR | B247: ELETROPAR | C247: Utilidade Pública | D247: Energia Elétrica | E247: Energia Elétrica
A248: LISTAGEM | B248: 0 | C248: Petróleo, Gás e Biocombustíveis | D248: Petróleo, Gás e Biocombustíveis | E248: Equipamentos e Serviços
A249: LISTAGEM | B249: 0 | C249: Materiais Básicos | D249: Materiais Diversos | E249: Materiais Diversos
...

Sheet IBOVESPA
A1: stDate | B1: Ticker | C1: Peso | D1: Nome | E1: SETOR ECONÔMICO | F1: SUBSETOR | G1: SEGMENTO
A2: 43990 | B2: VALE3 | C2: 0.1022485 | D2: =VLOOKUP(LEFT(B2,4),Tabela_Auxiliar!$A:$E,2,FALSE) -> VALE | E2: =VLOOKUP(LEFT(B2,4),Tabela_Auxiliar!$A:$E,3,FALSE) -> Materiais Básicos | F2: =VLOOKUP(LEFT(B2,4),Tabela_Auxiliar!$A:$E,4,FALSE) -> Mineração | G2: =VLOOKUP(LEFT(B2,4),Tabela_Auxiliar!$A:$E,5,FALSE) -> Minerais Metálicos
A3: 43990 | B3: ITUB4 | C3: 0.07619501 | D3: =VLOOKUP(LEFT(B3,4),Tabela_Auxiliar!$A:$E,2,FALSE) -> ITAUUNIBANCO | E3: =VLOOKUP(LEFT(B3,4),Tabela_Auxiliar!$A:$E,3,FALSE) -> Financeiro | F3: =VLOOKUP(LEFT(B3,4),Tabela_Auxiliar!$A:$E,5,FALSE) -> Bancos | G3: =VLOOKUP(LEFT(B3,4),Tabela_Auxiliar!$A:$E,5,FALSE) -> Bancos | J3: %IBOV
A4: 43990 | B4: B3SA3 | C4: 0.05999878 | D4: =VLOOKUP(LEFT(B4,4),Tabela_Auxiliar!$A:$E,2,FALSE) -> B3 | E4: =VLOOKUP(LEFT(B4,4),Tabela_Auxiliar!$A:$E,3,FALSE) -> Financeiro | F4: =VLOOKUP(LEFT(B4,4),Tabela_Auxiliar!$A:$E,5,FALSE) -> Serviços Financeiros Diversos | G4: =VLOOKUP(LEFT(B4,4),Tabela_Auxiliar!$A:$E,5,FALSE) -> Serviços Financeiros Diversos | I4: Financeiro | J4: 0.31608524
A5: 43990 | B5: PETR4 | C5: 0.05774191 | D5: =VLOOKUP(LEFT(B5,4),Tabela_Auxiliar!$A:$E,2,FALSE) -> PETROBRAS | E5: =VLOOKUP(LEFT(B5,4),Tabela_Auxiliar!$A:$E,3,FALSE) -> Petróleo, Gás e Biocombustíveis | F5: =VLOOKUP(LEFT(B5,4),Tabela_Auxiliar!$A:$E,5,FALSE) -> Exploração, Refino e Distribuição | G5: =VLOOKUP(LEFT(B5,4),Tabela_Auxiliar!$A:$E,5,FALSE) -> Exploração, Refino e Distribuição | I5: Bancos | J5: 0.21806568
A6: 43990 | B6: BBDC4 | C6: 0.05671063 | D6: =VLOOKUP(LEFT(B6,4),Tabela_Auxiliar!$A:$E,2,FALSE) -> BRADESCO | E6: =VLOOKUP(LEFT(B6,4),Tabela_Auxiliar!$A:$E,3,FALSE) -> Financeiro | F6: =VLOOKUP(LEFT(B6,4),Tabela_Auxiliar!$A:$E,5,FALSE) -> Bancos | G6: =VLOOKUP(LEFT(B6,4),Tabela_Auxiliar!$A:$E,5,FALSE) -> Bancos | I6: Bancos | J6: 0.21806568
A7: 43990 | B7: PETR3 | C7: 0.03905364 | D7: =VLOOKUP(LEFT(B7,4),Tabela_Auxiliar!$A:$E,2,FALSE) -> PETROBRAS | E7: =VLOOKUP(LEFT(B7,4),Tabela_Auxiliar!$A:$E,3,FALSE) -> Petróleo, Gás e Biocombustíveis | F7: =VLOOKUP(LEFT(B7,4),Tabela_Auxiliar!$A:$E,5,FALSE) -> Exploração, Refino e Distribuição | G7: =VLOOKUP(LEFT(B7,4),Tabela_Auxiliar!$A:$E,5,FALSE) -> Exploração, Refino e Distribuição | I7: Serviços Financeiros Diversos | J7: 0.06294106
A8: 43990 | B8: ABEV3 | C8: 0.0360444 | D8: =VLOOKUP(LEFT(B8,4),Tabela_Auxiliar!$A:$E,2,FALSE) -> AMBEV S/A | E8: =VLOOKUP(LEFT(B8,4),Tabela_Auxiliar!$A:$E,3,FALSE) -> Consumo não Cíclico | F8: =VLOOKUP(LEFT(B8,4),Tabela_Auxiliar!$A:$E,5,FALSE) -> Cervejas e Refrigerantes | G8: =VLOOKUP(LEFT(B8,4),Tabela_Auxiliar!$A:$E,5,FALSE) -> Cervejas e Refrigerantes | I8: Serviços Financeiros Diversos | J8: 0.06294106
A9: 43990 | B9: BBAS3 | C9: 0.02926678 | D9: =VLOOKUP(LEFT(B9,4),Tabela_Auxiliar!$A:$E,2,FALSE) -> BRASIL | E9: =VLOOKUP(LEFT(B9,4),Tabela_Auxiliar!$A:$E,3,FALSE) -> Financeiro | F9: =VLOOKUP(LEFT(B9,4),Tabela_Auxiliar!$A:$E,5,FALSE) -> Bancos | G9: =VLOOKUP(LEFT(B9,4),Tabela_Auxiliar!$A:$E,5,FALSE) -> Bancos | I9: Seguradoras | J9: 0.02428349
A10: 43990 | B10: ITSA4 | C10: 0.02649982 | D10: =VLOOKUP(LEFT(B10,4),Tabela_Auxiliar!$A:$E,2,FALSE) -> ITAUSA | E10: =VLOOKUP(LEFT(B10,4),Tabela_Auxiliar!$A:$E,3,FALSE) -> Financeiro | F10: =VLOOKUP(LEFT(B10,4),Tabela_Auxiliar!$A:$E,5,FALSE) -> Bancos | G10: =VLOOKUP(LEFT(B10,4),Tabela_Auxiliar!$A:$E,5,FALSE) -> Bancos | I10: Seguradoras | J10: 0.02428349
A11: 43990 | B11: MGLU3 | C11: 0.02340821 | D11: =VLOOKUP(LEFT(B11,4),Tabela_Auxiliar!$A:$E,2,FALSE) -> MAGAZ LUIZA | E11: =VLOOKUP(LEFT(B11,4),Tabela_Auxiliar!$A:$E,3,FALSE) -> Consumo Cíclico | F11: =VLOOKUP(LEFT(B11,4),Tabela_Auxiliar!$A:$E,5,FALSE) -> Eletrodomésticos | G11: =VLOOKUP(LEFT(B11,4),Tabela_Auxiliar!$A:$E,5,FALSE) -> Eletrodomésticos | I11: Exploração de Imóveis | J11: 0.01079501
A12: 43990 | B12: LREN3 | C12: 0.02057546 | D12: =VLOOKUP(LEFT(B12,4),Tabela_Auxiliar!$A:$E,2,FALSE) -> LOJAS RENNER | E12: =VLOOKUP(LEFT(B12,4),Tabela_Auxiliar!$A:$E,3,FALSE) -> Consumo Cíclico | F12: =VLOOKUP(LEFT(B12,4),Tabela_Auxiliar!$A:$E,5,FALSE) -> Tecidos, Vestuário e Calçados | G12: =VLOOKUP(LEFT(B12,4),Tabela_Auxiliar!$A:$E,5,FALSE) -> Tecidos, Vestuário e Calçados | I12: Exploração de Imóveis | J12: 0.01079501
A13: 43990 | B13: JBSS3 | C13: 0.02011443 | D13: =VLOOKUP(LEFT(B13,4),Tabela_Auxiliar!$A:$E,2,FALSE) -> JBS | E13: =VLOOKUP(LEFT(B13,4),Tabela_Auxiliar!$A:$E,3,FALSE) -> Consumo não Cíclico | F13: =VLOOKUP(LEFT(B13,4),Tabela_Auxiliar!$A:$E,5,FALSE) -> Carnes e Derivados | G13: =VLOOKUP(LEFT(B13,4),Tabela_Auxiliar!$A:$E,5,FALSE) -> Carnes e Derivados | I13: Materiais Básicos | J13: 0.15214913
A14: 43990 | B14: WEGE3 | C14: 0.01789904 | D14: =VLOOKUP(LEFT(B14,4),Tabela_Auxiliar!$A:$E,2,FALSE) -> WEG | E14: =VLOOKUP(LEFT(B14,4),Tabela_Auxiliar!$A:$E,3,FALSE) -> Bens Industriais | F14: =VLOOKUP(LEFT(B14,4),Tabela_Auxiliar!$A:$E,5,FALSE) -> Motores, Compressores e Outros | G14: =VLOOKUP(LEFT(B14,4),Tabela_Auxiliar!$A:$E,5,FALSE) -> Motores, Compressores e Outros | I14: Mineração | J14: 0.1022485
A15: 43990 | B15: GNDI3 | C15: 0.01669573 | D15: =VLOOKUP(LEFT(B15,4),Tabela_Auxiliar!$A:$E,2,FALSE) -> INTERMEDICA | E15: =VLOOKUP(LEFT(B15,4),Tabela_Auxiliar!$A:$E,3,FALSE) -> Saúde | F15: =VLOOKUP(LEFT(B15,4),Tabela_Auxiliar!$A:$E,5,FALSE) -> Análises e Diagnósticos | G15: =VLOOKUP(LEFT(B15,4),Tabela_Auxiliar!$A:$E,5,FALSE) -> Análises e Diagnósticos | I15: Minerais Metálicos | J15: 0.1022485
... A76: 43990 | B76: HGTX3 | C76: 0.00120953 | D76: =VLOOKUP(LEFT(B76,4),Tabela_Auxiliar!$A:$E,2,FALSE) -> CIA HERING | E76: =VLOOKUP(LEFT(B76,4),Tabela_Auxiliar!$A:$E,3,FALSE) -> Consumo Cíclico | F76: =VLOOKUP(LEFT(B76,4),Tabela_Auxiliar!$A:$E,5,FALSE) -> Vestuário | G76: =VLOOKUP(LEFT(B76,4),Tabela_Auxiliar!$A:$E,5,FALSE) -> Vestuário | I76: Telecomunicações | J76: 0.01803807
I77: Tecnologia da Informação | J77: 0.00481001
I78: Programas e Serviços | J78: 0.00481001
I79: Programas e Serviços | J79: 0.00481001
I80: Grand Total | J80: 1
